Traceback (most recent call last):
  File "contactmap.py", line 54, in <module>
    main()
  File "contactmap.py", line 48, in main
    y = np.loadtxt('data_out\contacts.txt')[:args.m, :args.m]
  File "/home/erschultz/miniconda3/envs/python3.8_pytorch1.8.1_cuda10.2/lib/python3.8/site-packages/numpy/lib/npyio.py", line 1065, in loadtxt
    fh = np.lib._datasource.open(fname, 'rt', encoding=encoding)
  File "/home/erschultz/miniconda3/envs/python3.8_pytorch1.8.1_cuda10.2/lib/python3.8/site-packages/numpy/lib/_datasource.py", line 194, in open
    return ds.open(path, mode, encoding=encoding, newline=newline)
  File "/home/erschultz/miniconda3/envs/python3.8_pytorch1.8.1_cuda10.2/lib/python3.8/site-packages/numpy/lib/_datasource.py", line 531, in open
    raise IOError("%s not found." % path)
OSError: data_out\contacts.txt not found.
/tmp/slurmd/job12660886/slurm_script: line 38: i#: command not found
